Workbook
Name NativeTimeline_Order_Date: #N/A
Name Slicer_Category: #N/A
Name Slicer_Region: #N/A
Name Slicer_Year: #N/A

Sheet Raw_Sales_Data
A1: Order_ID | B1: Raw_Order_Date | C1: Raw_Salesperson | D1: Raw_Region | E1: Raw_Product_Code | F1: Product_Name | G1: Raw_Units_Sold | H1: Raw_Unit_Price | I1: Cost_Price | J1: Payment_Method | K1: Raw_Payment_Status
A2: ORD-10001 | B2: 2026-06-08 | C2: priya patel | D2: EAST | E2: PRD-ACC-302 | F2: Noise Cancelling Headphones | G2: 12 | H2: 12500 | I2: 8267 | J2: UPI | K2: Paid
A3: ORD-10002 | B3: 2025-11-13 | C3: neha gupta | D3: EAST | E3: PRD-ACC-301 | F3: USB-C Docking Station | G3: 13 | H3: 8500 | I3: 5143 | J3: Credit Card | K3: pending
A4: ORD-10003 | B4: 2026-05-22 | C4: pooja sharma | D4: West | E4: PRD-FUR-201 | F4: Ergonomic Desk Chair | G4: 3 | H4: 14000 | I4: 10441 | J4: COD | K4: Paid
A5: ORD-10004 | B5: 2025-03-18 | C5: VIKRAM SINGH | D5: East | E5: PRD-ACC-302 | F5: Noise Cancelling Headphones | G5: 10 | H5: ₹ 12,500 | I5: 8801 | J5: Credit Card | K5: PENDING
A6: ORD-10005 | B6: 2025-10-12 | C6: VIKRAM SINGH | D6: south | E6: PRD-FUR-202_v1 | F6: Standing Executive Desk | G6: 8 | H6: 35000 | I6: 22572 | J6: UPI | K6: PENDING
A7: ORD-10006 | B7: 24/11/2025 | C7: VIKRAM SINGH | D7: Central | E7: PRD-ELE-101 | F7: Monitor 27inch | G7: 11 | H7: 55000 | I7: 38919 | J7: COD | K7: pending
A8: ORD-10007 | B8: 2026-04-09 | C8: priya patel | D8: north | E8: PRD-ELE-105 | F8: Android Tablet 10inch | G8: 5 | H8: INR 28000 | I8: 21639 | J8: COD | K8: paid
A9: ORD-10008 | B9: 2026-06-27 | C9: Rahul Sharma | D9: Central | E9: PRD-ACC-302 | F9: Noise Cancelling Headphones | G9: 9 pcs | H9: ₹ 12,500 | I9: 9201 | J9: Net Banking | K9: Failed
A10: ORD-10009 | B10: 2025-02-17 | C10: Ananya Roy | D10: north | E10: PRD-ELE-104 | F10: Core i7 Laptop | G10: 10 | H10: 75000 | I10: 52501 | J10: Net Banking | K10: Failed
A11: ORD-10010 | B11: 2025-04-03 | C11: priya patel | D11: EAST | E11: PRD-FUR-201_v1 | F11: Ergonomic Desk Chair | G11: 4 | H11: 14000 | I11: 10260 | J11: Cash on Delivery | K11: PENDING
A12: ORD-10011 | B12: 2025.09.08 | C12: Suresh Raina | D12: North | E12: PRD-ACC-301 | F12: USB-C Docking Station | G12: 7 | H12: 8500 | I12: 6184 | J12: Credit Card | K12: paid
A13: ORD-10012 | B13: 13/03/2025 | C13: Suresh Raina | D13: Central | E13: PRD-FUR-202 | F13: Standing Executive Desk | G13: 4 | H13: ₹ 35,000 | I13: 22680 | J13: Net Banking | K13: paid
... A35: ORD-10034 | B35: 2026-05-27 | C35: VIKRAM SINGH | D35: EAST | E35: PRD-ELE-101 | F35: Monitor 27inch | G35: 4 | H35: 55000 | I35: 34871 | J35: COD | K35: pending
A36: ORD-10035 | B36: 2025-08-12 | C36: VIKRAM SINGH | E36: PRD-ACC-302_v1 | F36: Noise Cancelling Headphones | G36: 13 | H36: INR 12500 | I36: 7503 | J36: Cash on Delivery | K36: PENDING
A37: ORD-10036 | B37: 20/03/2026 | C37: Rohan Verma | D37: East | E37: PRD-ELE-102 | F37: Mechanical Keyboard | G37: 10 | H37: ₹ 4,500 | I37: 3413 | J37: UPI | K37: pending
A38: ORD-10037 | B38: 2025-01-18 | C38: neha gupta | D38: West | E38: PRD-ELE-102 | F38: Mechanical Keyboard | G38: 8 | H38: 4500 | I38: 2705 | J38: Net Banking | K38: Paid
A39: ORD-10038 | B39: 2025-01-14 | C39: Ananya Roy | D39: Central | E39: PRD-ELE-103 | F39: Wireless Mouse | G39: 17 | H39: 2500 | I39: 1511 | J39: UPI | K39: Paid
A40: ORD-10039 | B40: 2026-05-20 | C40: Suresh Raina | D40: EAST | E40: PRD-FUR-201 | F40: Ergonomic Desk Chair | G40: 18 | H40: 14000 | I40: 9343 | J40: Cash on Delivery | K40: Paid
A41: ORD-10040 | B41: 2025-02-14 | C41: Rohan Verma | D41: West | E41: PRD-ELE-102_v3 | F41: Mechanical Keyboard | G41: 19 pcs | H41: ₹ 4,500 | I41: 2999 | J41: Credit Card | K41: pending
A42: ORD-10041 | B42: 2026-03-17 | C42: Rahul Sharma | D42: East | E42: PRD-ACC-302 | F42: Noise Cancelling Headphones | G42: 6 | H42: 12500 | I42: 7656 | J42: Cash on Delivery | K42: pending
A43: ORD-10042 | B43: 13/02/2025 | C43: Amit Kumar | D43: North | E43: PRD-FUR-201 | F43: Ergonomic Desk Chair | G43: 7 | H43: INR 14000 | I43: 9033 | J43: UPI | K43: paid
A44: ORD-10043 | B44: 2025-03-17 | C44: Suresh Raina | D44: Central | E44: PRD-ACC-301 | F44: USB-C Docking Station | G44: 10 | H44: 8500 | I44: 5453 | J44: UPI | K44: pending
A45: ORD-10044 | B45: 2025.04.02 | C45: Rahul Sharma | D45: EAST | E45: PRD-ELE-104 | F45: Core i7 Laptop | G45: 16 | H45: ₹ 75,000 | I45: 56812 | J45: Net Banking | K45: PENDING
A46: ORD-10045 | B46: 2026-01-23 | C46: pooja sharma | D46: East | E46: PRD-ELE-105_v2 | F46: Android Tablet 10inch | G46: 12 | H46: 28000 | I46: 16935 | J46: Credit Card
A47: ORD-10046 | B47: 2025-03-24 | C47: Amit Kumar | D47: East | E47: PRD-ACC-301 | F47: USB-C Docking Station | G47: 15 | H47: 8500 | I47: 5585 | J47: Cash on Delivery | K47: PENDING
A48: ORD-10047 | B48: 2026-03-03 | C48: Rohan Verma | D48: East | E48: PRD-ELE-105 | F48: Android Tablet 10inch | G48: 2 | H48: 28000 | I48: 19913 | J48: Net Banking | K48: Paid
A49: ORD-10048 | B49: 03/06/2025 | C49: Rahul Sharma | D49: North | E49: PRD-ELE-105 | F49: Android Tablet 10inch | G49: 14 pcs | H49: ₹ 28,000 | I49: 20306 | J49: Net Banking | K49: pending
A50: ORD-10049 | B50: 2025-03-12 | C50: priya patel | D50: West | E50: PRD-ELE-101 | F50: Monitor 27inch | G50: 18 | H50: INR 55000 | I50: 43704 | J50: UPI | K50: Failed
A51: ORD-10040 | B51: 2025-12-18 | C51: Rahul Sharma | D51: north | E51: PRD-ELE-102_v2 | F51: Mechanical Keyboard | G51: 17 | H51: 4500 | I51: 3145 | J51: COD | K51: paid
A52: ORD-10051 | B52: 2025-09-13 | C52: neha gupta | D52: north | E52: PRD-ACC-302 | F52: Noise Cancelling Headphones | G52: 11 | H52: 12500 | I52: 8576 | J52: Cash on Delivery | K52: Paid
A53: ORD-10052 | B53: 2025-04-06 | C53: Rahul Sharma | D53: East | E53: PRD-ELE-104 | F53: Core i7 Laptop | G53: 7 | H53: ₹ 75,000 | I53: 45542 | J53: Credit Card | K53: pending
A54: ORD-10053 | B54: 2026-02-02 | C54: Rahul Sharma | D54: North | E54: PRD-ACC-302 | F54: Noise Cancelling Headphones | G54: 3 | H54: 12500 | I54: 7524 | J54: UPI | K54: Failed
A55: ORD-10054 | B55: 08/04/2025 | C55: Rahul Sharma | D55: East | E55: PRD-ELE-104 | F55: Core i7 Laptop | G55: 5 | H55: 75000 | I55: 56214 | J55: COD | K55: Paid
A56: ORD-10055 | B56: 2026.04.20 | C56: Amit Kumar | D56: north | E56: PRD-ELE-104_v2 | F56: Core i7 Laptop | G56: 13 | H56: 75000 | I56: 50799 | J56: Net Banking | K56: paid
A57: ORD-10056 | B57: 2025-09-21 | C57: Amit Kumar | D57: North | E57: PRD-ACC-301 | F57: USB-C Docking Station | G57: 3 pcs | H57: ₹ 8,500 | I57: 5667 | J57: Cash on Delivery | K57: PENDING
A58: ORD-10057 | B58: 2025-05-12 | C58: Ananya Roy | D58: Central | E58: PRD-ELE-103 | F58: Wireless Mouse | G58: 6 | H58: 2500 | I58: 1948 | J58: Net Banking | K58: Paid
... A70: ORD-10069 | B70: 2026-04-22 | C70: Amit Kumar | D70: West | E70: PRD-ELE-103 | F70: Wireless Mouse | G70: 15 | H70: 2500 | I70: 1740 | J70: COD | K70: Paid
A71: ORD-10070 | B71: 2025-01-14 | C71: Amit Kumar | E71: PRD-FUR-202_v2 | F71: Standing Executive Desk | G71: 9 | H71: INR 35000 | I71: 27966 | J71: Net Banking | K71: Failed
A72: ORD-10071 | B72: 2025-07-16 | C72: neha gupta | D72: North | E72: PRD-ELE-101 | F72: Monitor 27inch | G72: 2 | H72: 55000 | I72: 43496 | J72: Cash on Delivery | K72: Failed
...

Sheet Raw_Product_Catalog
A1: Product_Code | B1: Product_Name | C1: Category | D1: Standard_Price
A2: PRD-ELE-101 | B2: Monitor 27inch | C2: Electronics | D2: 55000
A3: PRD-ELE-102 | B3: Mechanical Keyboard | C3: Electronics | D3: 4500
A4: PRD-ELE-103 | B4: Wireless Mouse | C4: Electronics | D4: 2500
A5: PRD-FUR-201 | B5: Ergonomic Desk Chair | C5: Furniture | D5: 14000
A6: PRD-FUR-202 | B6: Standing Executive Desk | C6: accessories | D6: 35000
A7: PRD-ACC-301 | B7: USB-C Docking Station | C7: Accessories | D7: 8500
A8: PRD-ELE-104 | B8: Core i7 Laptop | C8: Electronics | D8: 75000
A9: PRD-ACC-302 | B9: Noise Cancelling Headphones | C9: Accessories | D9: 12500
A10: PRD-ELE-105 | B10: Android Tablet 10inch | C10: Electronics | D10: 28000

Sheet Clean_Sales_Data
A1: Order_ID | B1: Order_Date | C1: Salesperson | D1: Region | E1: Product_Code | F1: Product_Name | G1: Units_Sold | H1: Unit_Price | I1: Cost_Price | J1: Payment_Method | K1: Payment_Status | L1: Total_Sales | M1: Total_Cost | N1: Profit | O1: Profit_Margin% | P1: Category | Q1: Year | R1: Month | S1: Month_Year
A2: ORD-10001 | B2: 46181 | C2: Priya Patel | D2: East | E2: PRD-ACC-302 | F2: Noise Cancelling Headphones | G2: 12 | H2: 12500 | I2: 8267 | J2: UPI | K2: Paid | L2: =SUM(Clean_Data[[#This Row],[Units_Sold]]*Clean_Data[[#This Row],[Unit_Price]]) -> 150000 | M2: =Clean_Data[[#This Row],[Units_Sold]]*Clean_Data[[#This Row],[Cost_Price]] -> 99204 | N2: =Clean_Data[[#This Row],[Total_Sales]]-Clean_Data[[#This Row],[Total_Cost]] -> 50796 | O2: =Clean_Data[[#This Row],[Profit]]/Clean_Data[[#This Row],[Total_Sales]] -> 0.33864 | P2: =_xlfn.XLOOKUP(Clean_Data[[#This Row],[Product_Code]],Product_Catalog!A:A,Product_Catalog!C:C) -> Accessories | Q2: =IF(Clean_Data[[#This Row],[Order_Date]]="","",YEAR(Clean_Data[[#This Row],[Order_Date]])) -> 2026 | R2: =TEXT(Clean_Data[[#This Row],[Order_Date]],"mmm") -> Jun | S2: =TEXT(Clean_Data[[#This Row],[Order_Date]],"mmm-yy") -> Jun-26
A3: ORD-10002 | B3: 45974 | C3: Neha Gupta | D3: East | E3: PRD-ACC-301 | F3: USB-C Docking Station | G3: 13 | H3: 8500 | I3: 5143 | J3: Credit Card | K3: Pending | L3: =SUM(Clean_Data[[#This Row],[Units_Sold]]*Clean_Data[[#This Row],[Unit_Price]]) -> 110500 | M3: =Clean_Data[[#This Row],[Units_Sold]]*Clean_Data[[#This Row],[Cost_Price]] -> 66859 | N3: =Clean_Data[[#This Row],[Total_Sales]]-Clean_Data[[#This Row],[Total_Cost]] -> 43641 | O3: =Clean_Data[[#This Row],[Profit]]/Clean_Data[[#This Row],[Total_Sales]] -> 0.39494118 | P3: =_xlfn.XLOOKUP(Clean_Data[[#This Row],[Product_Code]],Product_Catalog!A:A,Product_Catalog!C:C) -> Accessories | Q3: =IF(Clean_Data[[#This Row],[Order_Date]]="","",YEAR(Clean_Data[[#This Row],[Order_Date]])) -> 2025 | R3: =TEXT(Clean_Data[[#This Row],[Order_Date]],"mmm") -> Nov | S3: =TEXT(Clean_Data[[#This Row],[Order_Date]],"mmm-yy") -> Nov-25
A4: ORD-10003 | B4: 46164 | C4: Pooja Sharma | D4: West | E4: PRD-FUR-201 | F4: Ergonomic Desk Chair | G4: 3 | H4: 14000 | I4: 10441 | J4: Cash on Delivery | K4: Paid | L4: =SUM(Clean_Data[[#This Row],[Units_Sold]]*Clean_Data[[#This Row],[Unit_Price]]) -> 42000 | M4: =Clean_Data[[#This Row],[Units_Sold]]*Clean_Data[[#This Row],[Cost_Price]] -> 31323 | N4: =Clean_Data[[#This Row],[Total_Sales]]-Clean_Data[[#This Row],[Total_Cost]] -> 10677 | O4: =Clean_Data[[#This Row],[Profit]]/Clean_Data[[#This Row],[Total_Sales]] -> 0.25421429 | P4: =_xlfn.XLOOKUP(Clean_Data[[#This Row],[Product_Code]],Product_Catalog!A:A,Product_Catalog!C:C) -> Furniture | Q4: =IF(Clean_Data[[#This Row],[Order_Date]]="","",YEAR(Clean_Data[[#This Row],[Order_Date]])) -> 2026 | R4: =TEXT(Clean_Data[[#This Row],[Order_Date]],"mmm") -> May | S4: =TEXT(Clean_Data[[#This Row],[Order_Date]],"mmm-yy") -> May-26
A5: ORD-10004 | B5: 45734 | C5: Vikram Singh | D5: East | E5: PRD-ACC-302 | F5: Noise Cancelling Headphones | G5: 10 | H5: 12500 | I5: 8801 | J5: Credit Card | K5: Pending | L5: =SUM(Clean_Data[[#This Row],[Units_Sold]]*Clean_Data[[#This Row],[Unit_Price]]) -> 125000 | M5: =Clean_Data[[#This Row],[Units_Sold]]*Clean_Data[[#This Row],[Cost_Price]] -> 88010 | N5: =Clean_Data[[#This Row],[Total_Sales]]-Clean_Data[[#This Row],[Total_Cost]] -> 36990 | O5: =Clean_Data[[#This Row],[Profit]]/Clean_Data[[#This Row],[Total_Sales]] -> 0.29592 | P5: =_xlfn.XLOOKUP(Clean_Data[[#This Row],[Product_Code]],Product_Catalog!A:A,Product_Catalog!C:C) -> Accessories | Q5: =IF(Clean_Data[[#This Row],[Order_Date]]="","",YEAR(Clean_Data[[#This Row],[Order_Date]])) -> 2025 | R5: =TEXT(Clean_Data[[#This Row],[Order_Date]],"mmm") -> Mar | S5: =TEXT(Clean_Data[[#This Row],[Order_Date]],"mmm-yy") -> Mar-25
A6: ORD-10005 | B6: 45942 | C6: Vikram Singh | D6: South | E6: PRD-FUR-202 | F6: Standing Executive Desk | G6: 8 | H6: 35000 | I6: 22572 | J6: UPI | K6: Pending | L6: =SUM(Clean_Data[[#This Row],[Units_Sold]]*Clean_Data[[#This Row],[Unit_Price]]) -> 280000 | M6: =Clean_Data[[#This Row],[Units_Sold]]*Clean_Data[[#This Row],[Cost_Price]] -> 180576 | N6: =Clean_Data[[#This Row],[Total_Sales]]-Clean_Data[[#This Row],[Total_Cost]] -> 99424 | O6: =Clean_Data[[#This Row],[Profit]]/Clean_Data[[#This Row],[Total_Sales]] -> 0.35508571 | P6: =_xlfn.XLOOKUP(Clean_Data[[#This Row],[Product_Code]],Product_Catalog!A:A,Product_Catalog!C:C) -> Furniture | Q6: =IF(Clean_Data[[#This Row],[Order_Date]]="","",YEAR(Clean_Data[[#This Row],[Order_Date]])) -> 2025 | R6: =TEXT(Clean_Data[[#This Row],[Order_Date]],"mmm") -> Oct | S6: =TEXT(Clean_Data[[#This Row],[Order_Date]],"mmm-yy") -> Oct-25
A7: ORD-10006 | B7: 45985 | C7: Vikram Singh | D7: Central | E7: PRD-ELE-101 | F7: Monitor 27inch | G7: 11 | H7: 55000 | I7: 38919 | J7: Cash on Delivery | K7: Pending | L7: =SUM(Clean_Data[[#This Row],[Units_Sold]]*Clean_Data[[#This Row],[Unit_Price]]) -> 605000 | M7: =Clean_Data[[#This Row],[Units_Sold]]*Clean_Data[[#This Row],[Cost_Price]] -> 428109 | N7: =Clean_Data[[#This Row],[Total_Sales]]-Clean_Data[[#This Row],[Total_Cost]] -> 176891 | O7: =Clean_Data[[#This Row],[Profit]]/Clean_Data[[#This Row],[Total_Sales]] -> 0.29238182 | P7: =_xlfn.XLOOKUP(Clean_Data[[#This Row],[Product_Code]],Product_Catalog!A:A,Product_Catalog!C:C) -> Electronics | Q7: =IF(Clean_Data[[#This Row],[Order_Date]]="","",YEAR(Clean_Data[[#This Row],[Order_Date]])) -> 2025 | R7: =TEXT(Clean_Data[[#This Row],[Order_Date]],"mmm") -> Nov | S7: =TEXT(Clean_Data[[#This Row],[Order_Date]],"mmm-yy") -> Nov-25
A8: ORD-10007 | B8: 46121 | C8: Priya Patel | D8: North | E8: PRD-ELE-105 | F8: Android Tablet 10inch | G8: 5 | H8: 28000 | I8: 21639 | J8: Cash on Delivery | K8: Paid | L8: =SUM(Clean_Data[[#This Row],[Units_Sold]]*Clean_Data[[#This Row],[Unit_Price]]) -> 140000 | M8: =Clean_Data[[#This Row],[Units_Sold]]*Clean_Data[[#This Row],[Cost_Price]] -> 108195 | N8: =Clean_Data[[#This Row],[Total_Sales]]-Clean_Data[[#This Row],[Total_Cost]] -> 31805 | O8: =Clean_Data[[#This Row],[Profit]]/Clean_Data[[#This Row],[Total_Sales]] -> 0.22717857 | P8: =_xlfn.XLOOKUP(Clean_Data[[#This Row],[Product_Code]],Product_Catalog!A:A,Product_Catalog!C:C) -> Electronics | Q8: =IF(Clean_Data[[#This Row],[Order_Date]]="","",YEAR(Clean_Data[[#This Row],[Order_Date]])) -> 2026 | R8: =TEXT(Clean_Data[[#This Row],[Order_Date]],"mmm") -> Apr | S8: =TEXT(Clean_Data[[#This Row],[Order_Date]],"mmm-yy") -> Apr-26
A9: ORD-10008 | B9: 46200 | C9: Rahul Sharma | D9: Central | E9: PRD-ACC-302 | F9: Noise Cancelling Headphones | G9: 9 | H9: 12500 | I9: 9201 | J9: Net Banking | K9: Failed | L9: =SUM(Clean_Data[[#This Row],[Units_Sold]]*Clean_Data[[#This Row],[Unit_Price]]) -> 112500 | M9: =Clean_Data[[#This Row],[Units_Sold]]*Clean_Data[[#This Row],[Cost_Price]] -> 82809 | N9: =Clean_Data[[#This Row],[Total_Sales]]-Clean_Data[[#This Row],[Total_Cost]] -> 29691 | O9: =Clean_Data[[#This Row],[Profit]]/Clean_Data[[#This Row],[Total_Sales]] -> 0.26392 | P9: =_xlfn.XLOOKUP(Clean_Data[[#This Row],[Product_Code]],Product_Catalog!A:A,Product_Catalog!C:C) -> Accessories | Q9: =IF(Clean_Data[[#This Row],[Order_Date]]="","",YEAR(Clean_Data[[#This Row],[Order_Date]])) -> 2026 | R9: =TEXT(Clean_Data[[#This Row],[Order_Date]],"mmm") -> Jun | S9: =TEXT(Clean_Data[[#This Row],[Order_Date]],"mmm-yy") -> Jun-26
A10: ORD-10009 | B10: 45705 | C10: Ananya Roy | D10: North | E10: PRD-ELE-104 | F10: Core i7 Laptop | G10: 10 | H10: 75000 | I10: 52501 | J10: Net Banking | K10: Failed | L10: =SUM(Clean_Data[[#This Row],[Units_Sold]]*Clean_Data[[#This Row],[Unit_Price]]) -> 750000 | M10: =Clean_Data[[#This Row],[Units_Sold]]*Clean_Data[[#This Row],[Cost_Price]] -> 525010 | N10: =Clean_Data[[#This Row],[Total_Sales]]-Clean_Data[[#This Row],[Total_Cost]] -> 224990 | O10: =Clean_Data[[#This Row],[Profit]]/Clean_Data[[#This Row],[Total_Sales]] -> 0.29998667 | P10: =_xlfn.XLOOKUP(Clean_Data[[#This Row],[Product_Code]],Product_Catalog!A:A,Product_Catalog!C:C) -> Electronics | Q10: =IF(Clean_Data[[#This Row],[Order_Date]]="","",YEAR(Clean_Data[[#This Row],[Order_Date]])) -> 2025 | R10: =TEXT(Clean_Data[[#This Row],[Order_Date]],"mmm") -> Feb | S10: =TEXT(Clean_Data[[#This Row],[Order_Date]],"mmm-yy") -> Feb-25
A11: ORD-10010 | B11: 45750 | C11: Priya Patel | D11: East | E11: PRD-FUR-201 | F11: Ergonomic Desk Chair | G11: 4 | H11: 14000 | I11: 10260 | J11: Cash on Delivery | K11: Pending | L11: =SUM(Clean_Data[[#This Row],[Units_Sold]]*Clean_Data[[#This Row],[Unit_Price]]) -> 56000 | M11: =Clean_Data[[#This Row],[Units_Sold]]*Clean_Data[[#This Row],[Cost_Price]] -> 41040 | N11: =Clean_Data[[#This Row],[Total_Sales]]-Clean_Data[[#This Row],[Total_Cost]] -> 14960 | O11: =Clean_Data[[#This Row],[Profit]]/Clean_Data[[#This Row],[Total_Sales]] -> 0.26714286 | P11: =_xlfn.XLOOKUP(Clean_Data[[#This Row],[Product_Code]],Product_Catalog!A:A,Product_Catalog!C:C) -> Furniture | Q11: =IF(Clean_Data[[#This Row],[Order_Date]]="","",YEAR(Clean_Data[[#This Row],[Order_Date]])) -> 2025 | R11: =TEXT(Clean_Data[[#This Row],[Order_Date]],"mmm") -> Apr | S11: =TEXT(Clean_Data[[#This Row],[Order_Date]],"mmm-yy") -> Apr-25
A12: ORD-10011 | B12: 45908 | C12: Suresh Raina | D12: North | E12: PRD-ACC-301 | F12: USB-C Docking Station | G12: 7 | H12: 8500 | I12: 6184 | J12: Credit Card | K12: Paid | L12: =SUM(Clean_Data[[#This Row],[Units_Sold]]*Clean_Data[[#This Row],[Unit_Price]]) -> 59500 | M12: =Clean_Data[[#This Row],[Units_Sold]]*Clean_Data[[#This Row],[Cost_Price]] -> 43288 | N12: =Clean_Data[[#This Row],[Total_Sales]]-Clean_Data[[#This Row],[Total_Cost]] -> 16212 | O12: =Clean_Data[[#This Row],[Profit]]/Clean_Data[[#This Row],[Total_Sales]] -> 0.27247059 | P12: =_xlfn.XLOOKUP(Clean_Data[[#This Row],[Product_Code]],Product_Catalog!A:A,Product_Catalog!C:C) -> Accessories | Q12: =IF(Clean_Data[[#This Row],[Order_Date]]="","",YEAR(Clean_Data[[#This Row],[Order_Date]])) -> 2025 | R12: =TEXT(Clean_Data[[#This Row],[Order_Date]],"mmm") -> Sep | S12: =TEXT(Clean_Data[[#This Row],[Order_Date]],"mmm-yy") -> Sep-25
A13: ORD-10012 | B13: 45729 | C13: Suresh Raina | D13: Central | E13: PRD-FUR-202 | F13: Standing Executive Desk | G13: 4 | H13: 35000 | I13: 22680 | J13: Net Banking | K13: Paid | L13: =SUM(Clean_Data[[#This Row],[Units_Sold]]*Clean_Data[[#This Row],[Unit_Price]]) -> 140000 | M13: =Clean_Data[[#This Row],[Units_Sold]]*Clean_Data[[#This Row],[Cost_Price]] -> 90720 | N13: =Clean_Data[[#This Row],[Total_Sales]]-Clean_Data[[#This Row],[Total_Cost]] -> 49280 | O13: =Clean_Data[[#This Row],[Profit]]/Clean_Data[[#This Row],[Total_Sales]] -> 0.352 | P13: =_xlfn.XLOOKUP(Clean_Data[[#This Row],[Product_Code]],Product_Catalog!A:A,Product_Catalog!C:C) -> Furniture | Q13: =IF(Clean_Data[[#This Row],[Order_Date]]="","",YEAR(Clean_Data[[#This Row],[Order_Date]])) -> 2025 | R13: =TEXT(Clean_Data[[#This Row],[Order_Date]],"mmm") -> Mar | S13: =TEXT(Clean_Data[[#This Row],[Order_Date]],"mmm-yy") -> Mar-25
... A1157: ORD-11200 | B1157: 46179 | C1157: Neha Gupta | D1157: East | E1157: PRD-ACC-301 | F1157: USB-C Docking Station | G1157: 18 | H1157: 8500 | I1157: 5184 | J1157: Cash on Delivery | K1157: Pending | L1157: =SUM(Clean_Data[[#This Row],[Units_Sold]]*Clean_Data[[#This Row],[Unit_Price]]) -> 153000 | M1157: =Clean_Data[[#This Row],[Units_Sold]]*Clean_Data[[#This Row],[Cost_Price]] -> 93312 | N1157: =Clean_Data[[#This Row],[Total_Sales]]-Clean_Data[[#This Row],[Total_Cost]] -> 59688 | O1157: =Clean_Data[[#This Row],[Profit]]/Clean_Data[[#This Row],[Total_Sales]] -> 0.39011765 | P1157: =_xlfn.XLOOKUP(Clean_Data[[#This Row],[Product_Code]],Product_Catalog!A:A,Product_Catalog!C:C) -> Accessories | Q1157: =IF(Clean_Data[[#This Row],[Order_Date]]="","",YEAR(Clean_Data[[#This Row],[Order_Date]])) -> 2026 | R1157: =TEXT(Clean_Data[[#This Row],[Order_Date]],"mmm") -> Jun | S1157: =TEXT(Clean_Data[[#This Row],[Order_Date]],"mmm-yy") -> Jun-26

Sheet Product_Catalog
A1: Product_Code | B1: Product_Name | C1: Category | D1: Standard_Price
A2: PRD-ELE-101 | B2: Monitor 27inch | C2: Electronics | D2: 55000
A3: PRD-ELE-102 | B3: Mechanical Keyboard | C3: Electronics | D3: 4500
A4: PRD-ELE-103 | B4: Wireless Mouse | C4: Electronics | D4: 2500
A5: PRD-FUR-201 | B5: Ergonomic Desk Chair | C5: Furniture | D5: 14000
A6: PRD-FUR-202 | B6: Standing Executive Desk | C6: Furniture | D6: 35000
A7: PRD-ACC-301 | B7: USB-C Docking Station | C7: Accessories | D7: 8500
A8: PRD-ELE-104 | B8: Core i7 Laptop | C8: Electronics | D8: 75000
A9: PRD-ACC-302 | B9: Noise Cancelling Headphones | C9: Accessories | D9: 12500
A10: PRD-ELE-105 | B10: Android Tablet 10inch | C10: Electronics | D10: 28000

Sheet Pivot_Table
A3: Sum of Total_Sales | C3: Sum of Profit | E3: Profit Margin% | H3: Count of Order_ID | J3: Sum of Units_Sold
A4: 309130000 | C4: 93490092 | E4: =GETPIVOTDATA("Profit",$C$3)/GETPIVOTDATA("Total_Sales",$A$3) -> 0.3024297 | H4: 1156 | J4: 11674
A7: Row Labels | B7: Sum of Total_Sales | C7: Sum of Profit | E7: Row Labels | F7: Sum of Total_Sales | H7: Row Labels | I7: Sum of Total_Sales | K7: Row Labels | L7: Sum of Total_Sales
A8: Jan | B8: 25461000 | C8: 7684360 | E8: Central | F8: 40942000 | H8: Amit Kumar | I8: 36687500 | K8: Accessories | L8: 26563500
A9: Feb | B9: 33121000 | C9: 10044059 | E9: East | F9: 89135000 | H9: Ananya Roy | I9: 33976500 | K9: Furniture | L9: 60263000
A10: Mar | B10: 34840500 | C10: 10554067 | E10: North | F10: 87296500 | H10: Rahul Sharma | I10: 39354000 | K10: Electronics | L10: 222303500
A11: Apr | B11: 32150500 | C11: 9343954 | E11: South | F11: 50492000 | H11: Rohan Verma | I11: 40264500 | K11: Grand Total | L11: 309130000
A12: May | B12: 23887000 | C12: 7200164 | E12: West | F12: 41264500 | H12: Suresh Raina | I12: 41534000
A13: Jun | B13: 30089500 | C13: 8948596 | E13: Grand Total | F13: 309130000 | H13: Grand Total | I13: 191816500
A14: Jul | B14: 33419000 | C14: 10431069
A15: Aug | B15: 25702000 | C15: 7820052
A16: Sep | B16: 18710000 | C16: 5726915
A17: Oct | B17: 21834000 | C17: 6790574
A18: Nov | B18: 15661500 | C18: 4872101
A19: Dec | B19: 14254000 | C19: 4074181
A20: Grand Total | B20: 309130000 | C20: 93490092

Sheet Dashboard
